Workbook
Name Calls_Scores: raw_calls!$T$2:$T$1000
Name Deals_Amount: raw_deals!$C$2:$C$1000
Name Deals_ID: raw_deals!$A$2:$A$1000
Name USERS_ROLES_MAP: '⚙️ Настройки'!$J$10:$L$100
Name Deals_Stage: raw_deals!$D$2:$D$1000
Name Marketing_Leads: raw_marketing!$H$2:$H$1000
Name Deals_Source: raw_deals!$J$2:$J$1000
Name ROLES_LIST: '🔐 RBAC_Matrix'!$D$1:$J$1
Name Payments_Amount: raw_payments!$E$2:$E$1000
Name SHEETS_LIST: '🔐 RBAC_Matrix'!$A$2:$A$46
Name Deals_Manager: raw_deals!$H$2:$H$1000
Name Marketing_Spend: raw_marketing!$E$2:$E$1000
Name Payments_Type: raw_payments!$F$2:$F$1000
Name Deals_IsWon: raw_deals!$O$2:$O$1000

Sheet ⚡ Экспресс_Калькулятор_3_Цифры
B1: ⚡ ЭКСПРЕСС-КАЛЬКУЛЯТОР УПУЩЕННОЙ ПРИБЫЛИ ОП (ДИАГНОСТИКА ЗА 30 СЕКУНД)
A2: =HYPERLINK("#'📄 Executive_OnePager'!A1", "📄 1. One-Pager") | B2: =HYPERLINK("#'⚡ Пульс_Компании'!A1", "⚡ 2. Пульс компании") | C2: =HYPERLINK("#'📋 Пульт_РОПа_15_Минут'!A1", "📋 3. Пульт РОПа") | D2: =HYPERLINK("#'💸 Диагностика_Утечек_ОП'!A1", "💸 4. 7 Грехов ОП") | E2: =HYPERLINK("#'🎯 Action_Center'!A1", "🎯 5. Action Center") | F2: =HYPERLINK("#'🎙️ ИИ_Аудит'!A1", "🎙️ 6. ИИ-Аудит") | G2: =HYPERLINK("#'⚡ Экспресс_Калькулятор_3_Цифры'!A1", "⚡ 7. Экспресс 3 цифры") | H2: =HYPERLINK("#'🧪 QA_Suite'!A1", "🧪 8. QA Suite") | I2: =HYPERLINK("#'⚙️ Настройки'!A1", "⚙️ 9. Настройки")
A4: 🎛️ ВВЕДИТЕ 3 ЦИФРЫ ВАШЕГО БИЗНЕСА: | C4: 📊 БАЗОВЫЕ ПОКАЗАТЕЛИ (AS-IS): | G4: Категория капитала | H4: Объем, ₽
A5: 1. Входящий поток лидов в месяц (шт): | B5: 150 | C5: Емкость базы (при 100% конверсии): | D5: =B5 * B6 | G5: Факт выручки (As-Is) | H5: =D7
A6: 2. Средний чек закрытой сделки (₽): | B6: 400000 | C6: Текущая конверсия в оплату (факт): | D6: =D7/MAX(B5*B6, 1) | G6: Упущенная прибыль ОП | H6: =A11
A7: 3. Количество менеджеров в ОП (чел): | B7: 4 | C7: Текущая выручка месяца (факт): | D7: =calc_engine!B19 | G7: Потенциал кассы (To-Be) | H7: =C11
A8: Отраслевой сегмент компании: | B8: B2B Услуги / Производство | C8: Нагрузка на одного менеджера (лидов): | D8: =ROUND(B5 / MAX(B7,1), 0) & " лид/мес"
A10: 🔴 ВЫЯВЛЕННЫЙ РИСК ПОТЕРЬ | B10: 🟢 КОНСЕРВАТИВНЫЙ (+15%) | C10: 🚀 БАЗОВЫЙ ПЛАН (+30%) | D10: ⭐ ОПТИМИСТИЧНЫЙ (+50%)
A11: =SUM(D15:D18) | B11: =D7 + A11*0.15 | C11: =D7 + A11*0.3 | D11: =D7 + A11*0.5
A13: 📊 РАСШИФРОВКА ФИНАНСОВЫХ УТЕЧЕК ПО 4 УЗКИМ МЕСТАМ
A14: № | B14: Узкое место воронки продаж | C14: Отраслевой бенчмарк потерь | D14: Упущенная прибыль, ₽/мес | E14: Причина утечки | F14: Как закрываем за 14 дней
A15: 1 | B15: Слив лидов на звонках (нет Next Step) | C15: 28% выручки теряется из-за ошибок менеджеров на звонках (бенчмарк 2026) | D15: =ROUND(D7 * '⚙️ Настройки'!B43, 0) | E15: Менеджеры консультируют, но не закрывают на дату | F15: ИИ-аудит 100% звонков + чек-лист Next Step
A16: 2 | B16: Зависание сделок на этапе КП > 48ч | C16: 18% выручки теряется из-за просрочки follow-up | D16: =ROUND(D7 * '⚙️ Настройки'!B44, 0) | E16: Клиент остывает, пока менеджер ждет звонка | F16: Авторадар SLA 48ч + эскалация РОПу на 3-й день
A17: 3 | B17: Брошенные отказники без дожима (L1-L4) | C17: 12% — потенциал реактивации списанных отказников CRM | D17: =ROUND(D7 * '⚙️ Настройки'!B45, 0) | E17: Сделки списаны в архив без реактивации | F17: AI Recovery Engine: автодожим в WhatsApp/TG
A18: 4 | B18: Зависшая дебиторка и задержка оплат | C18: 10% выставленных счетов зависают на согласовании (DSO) | D18: =ROUND(D7 * '⚙️ Настройки'!B46, 0) | E18: Нет платежного календаря и контроля сроков | F18: Платежный календарь DSO + автонапоминания
B19: ИТОГО УПУЩЕННОЙ ПРИБЫЛИ В МЕСЯЦ: | D19: =SUM(D15:D18) | E19: ПОТЕНЦИАЛ БЫСТРОГО ВОЗВРАТА: | F19: =ROUND(D19 * '⚙️ Настройки'!B48, 0) & " ₽ в первый месяц"
A21: 🎁 СЛЕДУЮЩИЙ ШАГ: БЕСПЛАТНЫЙ ТЕСТ-ДРАЙВ НА 3 ВАШИХ ЗВОНКАХ
A22: Хотите проверить эту математику на реальных данных вашей компании за 15 минут?
A23: 👉 Отправьте 3 аудиозаписи любых вчерашних звонков ваших менеджеров в Telegram.
A24: ИИ бесплатно разберет их по 13 критериям, покажет ошибки речи и рассчитает точную сумму под угрозой слива.
A25: =HYPERLINK("https://ai-rop.ru/?utm_source=sheets_calculator", "🚀 ЗАПУСТИТЬ БЕСПЛАТНЫЙ ТЕСТ-ДРАЙВ НА 3 ЗВОНКАХ (ПЕРЕЙТИ НА AI-ROP.RU)")
A27: 🔒 Конфиденциально • Без передачи персональных данных • Экспресс-разбор за 15 минут (152-ФЗ РФ)

Sheet 📋 Пульт_РОПа_15_Минут
A1: =IF(ISNUMBER(SEARCH("CEO", '⚙️ Настройки'!$B$10)), "📋 СТРАТЕГИЧЕСКИЙ ПУЛЬТ СОБСТВЕННИКА: «5 РЕШЕНИЙ МЕСЯЦА»", IF(ISNUMBER(SEARCH("KAM", '⚙️ Настройки'!$B$10)), "📋 ЛИЧНЫЙ ACTION-LIST МЕНЕДЖЕРА НА СЕГОДНЯ (ПЕТРОВ А.)", IF(ISNUMBER(SEARCH("SDR", '⚙️ Настройки'!$B$10)), "📞 ПУЛЬТ ТЕЛЕМАРКЕТОЛОГА: «СКРИПТЫ И ГОРЯЧИЕ ЗВОНКИ»", IF(ISNUMBER(SEARCH("CMO", '⚙️ Настройки'!$B$10)), "📋 ПУЛЬТ ОПТИМИЗАЦИИ ТРАФИКА: «ТОЧКИ СЛИВА БЮДЖЕТА»", IF(ISNUMBER(SEARCH("CFO", '⚙️ Настройки'!$B$10)), "📋 ПЛАТЕЖНЫЙ КАЛЕНДАРЬ И ДЕБИТОРКА: «СРОЧНЫЕ СЧЕТА»", IF(OR(ISNUMBER(SEARCH("Admin", '⚙️ Настройки'!$B$10)), ISNUMBER(SEARCH("Администр", '⚙️ Настройки'!$B$10))), "🔧 ПУЛЬТ АДМИНИСТРАТОРА: «МОНИТОРИНГ И НАСТРОЙКИ СИСТЕМЫ»", "📋 ОПЕРАТИВНЫЙ ПУЛЬТ РОПа: «15 МИНУТ В ДЕНЬ»"))))))
A2: =HYPERLINK("#'📄 Executive_OnePager'!A1", "📄 1. One-Pager") | B2: =HYPERLINK("#'⚡ Пульс_Компании'!A1", "⚡ 2. Пульс компании") | C2: =HYPERLINK("#'📋 Пульт_РОПа_15_Минут'!A1", "📋 3. Пульт РОПа") | D2: =HYPERLINK("#'💸 Диагностика_Утечек_ОП'!A1", "💸 4. 7 Грехов ОП") | E2: =HYPERLINK("#'🎯 Action_Center'!A1", "🎯 5. Action Center") | F2: =HYPERLINK("#'🎙️ ИИ_Аудит'!A1", "🎙️ 6. ИИ-Аудит") | G2: =HYPERLINK("#'⚡ Экспресс_Калькулятор_3_Цифры'!A1", "⚡ 7. Экспресс 3 цифры") | H2: =HYPERLINK("#'🧪 QA_Suite'!A1", "🧪 8. QA Suite") | I2: =HYPERLINK("#'⚙️ Настройки'!A1", "⚙️ 9. Настройки")
A4: Звонков за вчера | B4: Диалогов с браком (<9) | C4: Сделок с угрозой срыва | D4: Сумма в зоне риска прямо сейчас | E4: Статус дня для РОПа
A5: =calc_engine!B41 | B5: =COUNTIFS(raw_calls!$T$2:$T50000, "<9") | C5: =COUNTIF(E9:E13, "*КРИТИЧЕСКИЙ*") | D5: =SUM(D9:D13) | E5: =IF(C5>0, "🚨 ТРЕБУЕТСЯ 15 МИНУТ КОНТРОЛЯ РОПа", "🟢 ВСЕ В РАБОЧЕМ ГРАФИКЕ")
A7: ="🎯 " & IF(ISNUMBER(SEARCH("CEO", '⚙️ Настройки'!$B$10)), "ТОП-5 СТРАТЕГИЧЕСКИХ РЕШЕНИЙ ДЛЯ ЗАЩИТЫ КАПИТАЛА БИЗНЕСА", IF(ISNUMBER(SEARCH("KAM", '⚙️ Настройки'!$B$10)), "МОЙ ПЕРСОНАЛЬНЫЙ СПИСОК ГОРЯЩИХ СДЕЛОК НА СЕГОДНЯ", IF(ISNUMBER(SEARCH("SDR", '⚙️ Настройки'!$B$10)), "ТОП-5 ЗВОНКОВ В РИСКЕ И СРОЧНАЯ КВАЛИФИКАЦИЯ ЛИДОВ", IF(ISNUMBER(SEARCH("CMO", '⚙️ Настройки'!$B$10)), "ТОП-5 ДЕЙСТВИЙ ПО ОПТИМИЗАЦИИ РЕКЛАМНЫХ КАМПАНИЙ", IF(ISNUMBER(SEARCH("CFO", '⚙️ Настройки'!$B$10)), "ТОП-5 СРОЧНЫХ ДЕЙСТВИЙ ПО СБОРУ ДЕБИТОРКИ И ЗАЩИТЕ КАССЫ", IF(OR(ISNUMBER(SEARCH("Admin", '⚙️ Настройки'!$B$10)), ISNUMBER(SEARCH("Администр", '⚙️ Настройки'!$B$10))), "ТОП-5 СИСТЕМНЫХ АЛЕРТОВ И ПРОВЕРКА ЦЕЛОСТНОСТИ REVOPS", "ТОП-5 СРОЧНЫХ ДЕЙСТВИЙ ДЛЯ РОПа НА СЕГОДНЯ (DAILY ACTION LIST)"))))))
A8: № | B8: Сделка / Контрагент | C8: Суть проблемы и симптом | D8: Сумма в риске | E8: Приоритет | F8: Срочное действие РОПа (Что сделать) | G8: Чекбокс | H8: 🤖 Сгенерированный оффер ИИ-дожима (WhatsApp / Скрипт РОПа)
A9: 1 | B9: Сделка D-104 (ООО «Вектор Плюс») | C9: Зависание на этапе КП: 12 дней без ответа (норма 48ч) | D9: =VLOOKUP("D-104", raw_deals!$A$2:$C$50000, 3, FALSE) | E9: 🔴 КРИТИЧЕСКИЙ | F9: Запросить статус у КАМа Петрова, согласовать скидку/рассрочку | G9: В РАБОТЕ | H9: ="Добрый день, Алексей! Вижу, наш расчет по договору согласован. Чтобы зафиксировать спецусловия октября со скидкой 7%, предлагаю сегодня подписать спецификацию. Слот для звонка: 14:30. Удобно?"
A10: 2 | B10: Звонок C-505 / Сделка D-109 (ООО «ПромКомплект») | C10: Менеджер сорвал контакт (балл речи 2/13), клиент ушел в отказ | D10: =VLOOKUP("D-109", raw_deals!$A$2:$C$50000, 3, FALSE) | E10: 🔴 КРИТИЧЕСКИЙ | F10: Личный звонок РОПа ЛПР до 12:00: перехват сделки от лица руководства | G10: В РАБОТЕ | H10: ="Михаил Сергеевич, добрый день! Это Дмитрий Иванов, коммерческий директор. Прослушал вчерашний диалог с нашим менеджером — приношу извинения за неполную консультацию. Лично подготовил для вас проект с расширенной гарантией 24 мес. Уделите 5 минут?"
A11: 3 | B11: Звонок C-503 / Сделка D-106 (ООО «СнабСервис») | C11: В диалоге не зафиксирована дата встречи (балл речи 6/13) | D11: =VLOOKUP("D-106", raw_deals!$A$2:$C$50000, 3, FALSE) | E11: 🟡 СРЕДНИЙ | F11: Поставить задачу менеджеру Петрову: перезвонить и назначить слот встречи | G11: В РАБОТЕ | H11: ="Игорь, приветствую! Направил вам 2 слота на онлайн-демо платформы: сегодня в 16:00 или завтра в 11:30. За 15 минут покажем связку с вашей CRM. Какой слот забронировать?"
A12: 4 | B12: Сделка D-107 (ООО «ТехноПром») | C12: Счет просрочен на 9 дней (сумма 150 000 ₽) | D12: =VLOOKUP("INV-203", raw_invoices!$A$2:$G$50000, 7, FALSE) | E12: 🟡 СРЕДНИЙ | F12: Отправить триггерное напоминание в WhatsApp бухгалтеру клиента | G12: В РАБОТЕ | H12: ="Ольга, здравствуйте! Бухгалтерия напоминает: по счету INV-203 сегодня крайний день резерва оборудования по льготному курсу. Выставить ссылку на моментальную оплату через СБП?"
A13: 5 | B13: Сделка D-103 (ООО «ИнвестХолдинг») | C13: Нагрузка 80%, 4 ключевые сделки висят на РОПе | D13: =calc_engine!E43 | E13: 🟡 СРЕДНИЙ | F13: Делегировать 2 входящие сделки на КАМа (у КАМа загрузка всего 4%) | G13: В РАБОТЕ | H13: ="Регламентное действие: передать права ответственного по сделке D-102 на КАМа Петрова (свободная емкость 75%). РОПу оставить контроль ключевых контрольных точек."
B14: ИТОГО ДЕНЕГ В ЗОНЕ РИСКА СЕГОДНЯ: | D14: =SUM(D9:D13) | E14: СПАСЕННАЯ ВЫРУЧКА: | F14: При выполнении всех 5 действий | G14: 100% защита
E17: ⏱️ ЭКСПРЕСС-РЕГЛАМЕНТ РОПа (15 МИНУТ/ДЕНЬ)
E18: 09:00 - 09:05 | F18: Проверка ночного ИИ-аудита: 2 звонка с браком (<9 баллов)
E19: 09:05 - 09:10 | F19: Перехват сделки D-109 (600 т.р.) и звонок ЛПР до 12:00
E20: 09:10 - 09:13 | F20: Согласование спецусловий по D-104 (850 т.р.)
E21: 09:13 - 09:15 | F21: Делегирование 2 сделок с РОПа на свободного КАМа
E22: Результат: | F22: 2 730 000 ₽ защищено от слива за 15 минут

Sheet 🎙️ ИИ_Аудит
A1: 🎙️ ИИ-СУПЕРВАЙЗЕР ЗВОНКОВ: РЕЧЕВАЯ АНАЛИТИКА 100% ДИАЛОГОВ (WHISPER LARGE V3 + LLM)
A2: =HYPERLINK("#'📄 Executive_OnePager'!A1", "📄 1. One-Pager") | B2: =HYPERLINK("#'⚡ Пульс_Компании'!A1", "⚡ 2. Пульс компании") | C2: =HYPERLINK("#'📋 Пульт_РОПа_15_Минут'!A1", "📋 3. Пульт РОПа") | D2: =HYPERLINK("#'💸 Диагностика_Утечек_ОП'!A1", "💸 4. 7 Грехов ОП") | E2: =HYPERLINK("#'🎯 Action_Center'!A1", "🎯 5. Action Center") | F2: =HYPERLINK("#'🎙️ ИИ_Аудит'!A1", "🎙️ 6. ИИ-Аудит") | G2: =HYPERLINK("#'⚡ Экспресс_Калькулятор_3_Цифры'!A1", "⚡ 7. Экспресс 3 цифры") | H2: =HYPERLINK("#'🧪 QA_Suite'!A1", "🧪 8. QA Suite") | I2: =HYPERLINK("#'⚙️ Настройки'!A1", "⚙️ 9. Настройки") | K2: 💸 7 Грехов ОП | N2: 📄 One-Pager | Q2: 🔐 152-ФЗ Контур Безопасности
A3: Проанализировано звонков | C3: Средний балл качества | E3: Фиксация жесткого Next Step | G3: Критический брак речи (<9) | J3: Выручка под угрозой слива | M3: Вердикт ИИ-супервайзера
A4: 25 звонков / сут | C4: 8.9 из 13 | E4: 60.0% (норма ≥85%) | G4: 6 диалогов | J4: 2,840,000 ₽ | M4: 🚨 ВЫСОКИЙ РИСК СЛИВА VIP-КЛИЕНТОВ (ТРЕБУЕТСЯ ВМЕШАТЕЛЬСТВО РОПа)
A6: 👥 РЕЙТИНГ МЕНЕДЖЕРОВ ОП ПО КАЧЕСТВУ РЕЧИ (ЛИДЕРБОРД РОПа)
A7: № | B7: Менеджер ОП | C7: Звонков | D7: Ср. балл /13 | E7: Next Step % | F7: Talk/Listen (норма ≥45%) | G7: Зависших сделок | H7: Сумма риска (₽) | I7: Грейд ИИ | J7: Статус и рекомендация РОПу
A8: 1 | B8: Алексей Мельников | C8: 6 | D8: 12.2 | E8: 100.0% | F8: 48% / 52% | G8: 0 | H8: 0 ₽ | I8: ⭐ А (Эталон) | J8: Эталонный скрипт, рекомендован в базу знаний компании
A9: 2 | B9: Елена Васильева | C9: 5 | D9: 10.8 | E9: 80.0% | F9: 51% / 49% | G9: 1 | H9: 160,000 ₽ | I9: 🟢 B (Норма) | J9: Высокая конверсия, мелкие замечания по регламенту встречи
A10: 3 | B10: Анна Соколова | C10: 5 | D10: 8.4 | E10: 60.0% | F10: 58% / 42% | G10: 2 | H10: 480,000 ₽ | I10: 🟡 C (Зона риска) | J10: Забывает фиксировать дату звонка, требуется тренинг
A11: 4 | B11: Дмитрий Ковалев | C11: 5 | D11: 6.2 | E11: 40.0% | F11: 72% / 28% | G11: 3 | H11: 1,100,000 ₽ | I11: 🔴 D (Брак речи) | J11: Срыв контакта, перебивание клиента, демпинг скидок
A12: 5 | B12: Иван Попов | C12: 4 | D12: 5.5 | E12: 25.0% | F12: 79% / 21% | G12: 3 | H12: 1,100,000 ₽ | I12: 🔴 D (Брак речи) | J12: Режим 'автоответчика', нет попыток закрытия на встречу
A13: ИТОГО ПО ОТДЕЛУ ПРОДАЖ: | C13: 25 | D13: 8.9 / 13 | E13: 60.0% | F13: 61% / 39% | G13: 9 | H13: 2,840,000 ₽ | I13: ⚠️ РИСК | J13: Требуется экспресс-коучинг по отработке возражений
A15: 🔍 ДЕТАЛИЗИРОВАННАЯ МАТРИЦА ОЦЕНКИ ЗВОНКОВ ПО ВСЕМ 13 КРИТЕРИЯМ (0 / 1)
A16: Call ID | B16: Сделка / Клиент | C16: Менеджер | D16: Сумма (₽) | E16: Длит. | F16: Этап CRM | G16: К1 NextStep | H16: К2 Иниц. | I16: К3 ЛПР | J16: К4 Боли | K16: К5 Дорого | L16: К6 Подумаю | M16: К7 Кейсы | N16: К8 Закрытие | O16: К9 Привет. | P16: К10 Речь | Q16: К11 Слушан. | R16: К12 Итог | S16: К13 Маржа | T16: Балл /13 | U16: Статус ИИ | V16: Сумма в риске, ₽
A17: C-501 | B17: D-101 (ООО Вектор Плюс) | C17: Мельников | D17: 850,000 ₽ | E17: 05:40 | F17: КП отправлено | G17: 1 | H17: 1 | I17: 1 | J17: 1 | K17: 1 | L17: 1 | M17: 1 | N17: 1 | O17: 1 | P17: 1 | Q17: 1 | R17: 1 | S17: 1 | T17: 13 | U17: ⭐ ЭТАЛОН | V17: 0 ₽
A18: C-502 | B18: D-104 (ООО Вектор Плюс) | C18: Васильева | D18: 850,000 ₽ | E18: 04:20 | F18: Переговоры | G18: 1 | H18: 1 | I18: 1 | J18: 1 | K18: 1 | L18: 0 | M18: 1 | N18: 1 | O18: 1 | P18: 1 | Q18: 1 | R18: 1 | S18: 1 | T18: 12 | U18: 🟢 В НОРМЕ | V18: 0 ₽
A19: C-503 | B19: D-106 (ООО СнабСервис) | C19: Соколова | D19: 280,000 ₽ | E19: 03:10 | F19: Встреча/Демо | G19: 0 | H19: 1 | I19: 1 | J19: 0 | K19: 1 | L19: 0 | M19: 1 | N19: 0 | O19: 1 | P19: 0 | Q19: 1 | R19: 0 | S19: 1 | T19: 7 | U19: ⚠️ РИСК | V19: 280,000 ₽
A20: C-504 | B20: D-107 (ООО ТехноПром) | C20: Соколова | D20: 150,000 ₽ | E20: 06:15 | F20: Квалификация | G20: 1 | H20: 1 | I20: 1 | J20: 0 | K20: 1 | L20: 1 | M20: 0 | N20: 0 | O20: 1 | P20: 1 | Q20: 0 | R20: 1 | S20: 1 | T20: 9 | U20: ⚠️ РИСК | V20: 150,000 ₽
A21: C-505 | B21: D-109 (ООО ПромКомплект) | C21: Ковалев | D21: 600,000 ₽ | E21: 03:30 | F21: КП отправлено | G21: 0 | H21: 0 | I21: 0 | J21: 0 | K21: 0 | L21: 0 | M21: 0 | N21: 0 | O21: 1 | P21: 0 | Q21: 0 | R21: 0 | S21: 1 | T21: 2 | U21: ❌ СЛИВ | V21: 600,000 ₽
A22: C-506 | B22: D-111 (ООО Глобал Инвест) | C22: Мельников | D22: 3,000,000 ₽ | E22: 07:15 | F22: Финальные условия | G22: 1 | H22: 1 | I22: 1 | J22: 1 | K22: 1 | L22: 1 | M22: 1 | N22: 1 | O22: 1 | P22: 1 | Q22: 1 | R22: 1 | S22: 1 | T22: 13 | U22: ⭐ ЭТАЛОН | V22: 0 ₽
A23: C-507 | B23: D-114 (ООО АльфаТрейд) | C23: Ковалев | D23: 500,000 ₽ | E23: 04:45 | F23: Дожим договора | G23: 0 | H23: 1 | I23: 1 | J23: 0 | K23: 0 | L23: 0 | M23: 1 | N23: 0 | O23: 1 | P23: 0 | Q23: 0 | R23: 1 | S23: 0 | T23: 5 | U23: ❌ СЛИВ | V23: 500,000 ₽
A24: C-508 | B24: D-118 (ООО СтройХолдинг) | C24: Попов | D24: 650,000 ₽ | E24: 02:50 | F24: Входящий лид | G24: 0 | H24: 0 | I24: 1 | J24: 0 | K24: 0 | L24: 0 | M24: 0 | N24: 0 | O24: 1 | P24: 1 | Q24: 0 | R24: 1 | S24: 0 | T24: 4 | U24: ❌ СЛИВ | V24: 650,000 ₽
A25: C-509 | B25: D-121 (ООО СпецМаш) | C25: Васильева | D25: 420,000 ₽ | E25: 05:10 | F25: Презентация КП | G25: 1 | H25: 1 | I25: 1 | J25: 1 | K25: 1 | L25: 1 | M25: 1 | N25: 0 | O25: 1 | P25: 1 | Q25: 1 | R25: 1 | S25: 1 | T25: 12 | U25: 🟢 В НОРМЕ | V25: 0 ₽
A26: C-510 | B26: D-125 (ООО МегаТранс) | C26: Попов | D26: 450,000 ₽ | E26: 03:40 | F26: Квалификация | G26: 0 | H26: 0 | I26: 0 | J26: 1 | K26: 1 | L26: 0 | M26: 1 | N26: 0 | O26: 1 | P26: 1 | Q26: 0 | R26: 1 | S26: 0 | T26: 6 | U26: ⚠️ РИСК | V26: 450,000 ₽
A27: ИТОГО ПОТЕРЬ И РИСКОВ ПО ЗВОНКАМ: | D27: 7,750,000 ₽ | T27: 8.9 ср. | U27: 6 сливов | V27: 2,840,000 ₽
A29: 🚨 РЕЕСТР ДЕФЕКТОВ РЕЧИ: РАСШИФРОВАННЫЕ ЦИТАТЫ ИЗ РАЗГОВОРОВ И РЕШЕНИЯ РОПа
A30: Call ID | B30: Сделка / Контрагент | C30: Менеджер | D30: Сумма в риске | E30: Критический дефект речи | G30: 💬 Цитата из диалога (Расшифровка Whisper Large V3) | N30: 🤖 Решение ИИ и Срочное действие РОПа
A31: C-505 | B31: D-109 (ООО «ПромКомплект») | C31: Дмитрий Ковалев | D31: 600,000 ₽ | E31: Срыв контакта / грубость при цене | G31: Клиент: «Почему у вас смета на 15% выше рынка?» → Менеджер: «Не знаю, везде всё дорожает. Не устраивает — берите у конкурентов без гарантии» | N31: 🚨 Экстренный звонок РОПа ЛПР до 12:00: принести извинения за консультацию, перехватить сделку, дать проект со спец-гарантией 24 мес.
A32: C-503 | B32: D-106 (ООО «СнабСервис») | C32: Анна Соколова | D32: 280,000 ₽ | E32: Слив жесткого Next Step (в никуда) | G32: Менеджер: «Я вам КП на почту сбросила, посмотрите когда время будет». Клиент: «Хорошо, если что наберу» | N32: Направить клиенту в WhatsApp 2 конкретных слота встречи (сегодня 16:00 / завтра 11:30) с демонстрацией интеграции с CRM.
A33: C-507 | B33: D-114 (ООО «АльфаТрейд») | C33: Дмитрий Ковалев | D33: 500,000 ₽ | E33: Необоснованная скидка вместо ценности | G33: Клиент: «У нас бюджет строго ограничен». Менеджер: «Ну ладно, согласую вам скидку 10% прямо сейчас» | N33: Заблокировать выставление счета со скидкой в CRM. РОПу пересогласовать условия: скидка 5% только в обмен на 100% предоплату за 24ч.
A34: C-508 | B34: D-118 (ООО «СтройХолдинг») | C34: Иван Попов | D34: 650,000 ₽ | E34: Слив возражения «Я подумаю» | G34: Клиент: «Нам нужно всё обдумать и посоветоваться с руководством». Менеджер: «Да, конечно, думайте» (повесил трубку) | N34: Передать лида старшему КАМу. Отправить в WhatsApp отраслевой кейс с аналогичным объектом и окупаемостью за 21 день.
A35: C-510 | B35: D-125 (ООО «МегаТранс») | C35: Иван Попов | D35: 450,000 ₽ | E35: Режим автоответчика, не выявлен ЛПР | G35: Менеджер 5 минут зачитывал прайс-лист секретарю, не спросив, кто принимает решение по закупкам | N35: Разбор на летучке: регламент квалификации BANT. Назначить повторный звонок с прямым выходом на генерального директора.
A37: 📋 ЭТАЛОННЫЙ СТАНДАРТ 13 КРИТЕРИЕВ ОЦЕНКИ B2B-ДИАЛОГОВ (WHISPER LARGE V3 + LLM SUPERVISOR)
A38: № | B38: Параметр оценки диалога | C38: Вес | D38: Приоритет | E38: Что проверяет алгоритм ИИ (Суть критерия) | H38: Маркеры дефекта в речи (Почему сделка срывается) | M38: Coaching Tip: как обучить менеджера и защитить выручку
A39: 1 | B39: Жёсткий Next Step | C39: 2.0x | D39: 🔴 P0 (Критический) | E39: Зафиксирована точная дата и время следующего контакта (календарный слот) | H39: «Я вам наберу на днях», «Подумайте, позвоните», отпускание без дедлайна | M39: Внедрить обязательный вопрос: «Во вторник в 14:30 или в среду в 11:00 удобно?»
A40: 2 | B40: Инициатива диалога | C40: 1.0x | D40: 🟡 P1 (Высокий) | E40: Менеджер ведёт диалог вопросами, держит сценарий, а не работает автоответчиком | H40: Клиент задает все вопросы сам, менеджер только пассивно отвечает | M40: Правило «Ответ + Встречный вопрос». Завершать каждую реплику вопросом.
A41: 3 | B41: Квалификация ЛПР / ЛВПР | C41: 1.5x | D41: 🔴 P0 (Критический) | E41: Установлен статус собеседника: принимает ли решения по бюджету и согласованию | H41: Трата 40 минут на презентацию секретарю или инженеру без полномочий | M41: «Кто кроме вас участвует в утверждении финансового бюджета проекта?»
A42: 4 | B42: Выявление болей и срочности | C42: 1.2x | D42: 🟡 P1 (Высокий) | E42: Понятна ли бизнес-задача клиента, текущие потери и дедлайн решения проблемы | H42: Менеджер презентует продукт 'в лоб', не узнав реальную боль клиента | M42: Сначала диагностика по методологии SPIN/BANT, затем презентация под боль.
A43: 5 | B43: Отработка возражения «Дорого» | C43: 1.5x | D43: 🔴 P0 (Критический) | E43: Обоснование ценности, расчет ROI/окупаемости, рассрочка (без моментальной скидки) | H43: Моментальная скидка при первом сомнении или согласие («Да, у нас недешево») | M43: Показать окупаемость: сколько клиент теряет каждый день без решения.
A44: 6 | B44: Отработка «Я подумаю» | C44: 1.0x | D44: 🟡 P1 (Высокий) | E44: Вскрытие истинного сомнения клиента, а не молчаливое отпускание в архив | H44: «Хорошо, думайте, ждем звонка», закрытие звонка на неопределенности | M44: «Алексей, обычно говорят 'подумаю', если смущает цена или функционал. Что именно?»
...

Sheet 💸 Диагностика_Утечек_ОП
A1: 💸 ДИАГНОСТИЧЕСКИЙ АУДИТ УПУЩЕННОЙ ПРИБЫЛИ И УЗКИХ МЕСТ ОТДЕЛА ПРОДАЖ
A2: =HYPERLINK("#'📄 Executive_OnePager'!A1", "📄 1. One-Pager") | B2: =HYPERLINK("#'⚡ Пульс_Компании'!A1", "⚡ 2. Пульс компании") | C2: =HYPERLINK("#'📋 Пульт_РОПа_15_Минут'!A1", "📋 3. Пульт РОПа") | D2: =HYPERLINK("#'💸 Диагностика_Утечек_ОП'!A1", "💸 4. 7 Грехов ОП") | E2: =HYPERLINK("#'🎯 Action_Center'!A1", "🎯 5. Action Center") | F2: =HYPERLINK("#'🎙️ ИИ_Аудит'!A1", "🎙️ 6. ИИ-Аудит") | G2: =HYPERLINK("#'⚡ Экспресс_Калькулятор_3_Цифры'!A1", "⚡ 7. Экспресс 3 цифры") | H2: =HYPERLINK("#'🧪 QA_Suite'!A1", "🧪 8. QA Suite") | I2: =HYPERLINK("#'⚙️ Настройки'!A1", "⚙️ 9. Настройки")
A4: Фактическая выручка месяца | B4: Взвешенный пайплайн в работе | C4: Выявленная упущенная прибыль | D4: Потенциал выручки (To-Be) | E4: Ожидаемый чистый ROI | F4: Срок окупаемости проекта
A5: =calc_engine!B19 | B5: =calc_engine!B18 | C5: =E16 | D5: =A5 + E16 | E5: =B23 | F5: =B24
A7: 🔴 7 СМЕРТНЫХ ГРЕХОВ ОТДЕЛА ПРОДАЖ (АНАТОМИЯ СБОЕВ И ИХ УСТРАНЕНИЕ)
A8: № | B8: Смертный грех ОП (Системный сбой) | C8: Симптом и диагностика в компании | D8: Объем базы в риске | E8: Упущенная выгода / Риск, ₽ | F8: Приоритет | G8: Как закрывает наша платформа | H8: Ожидаемый эффект
A9: 1 | B9: «Черный ящик» CRM: иллюзорный пайплайн | C9: В CRM висит 5.3 млн ₽, но реальный взвешенный объем всего 2.6 млн ₽. Фаундер живет в иллюзии плана | D9: =calc_engine!B17 | E9: =calc_engine!B17 - calc_engine!B18 | F9: 🔴 P0 (Критический) | G9: Взвешенный прогноз воронки (SSOT) + исключение зомби-сделок | H9: 100% точность прогноза Run-Rate без иллюзий
A10: 2 | B10: «Кладбище сделок»: срыв регламентов SLA | C10: Сделки маринуются на этапе КП по 12–14 дней (норма 48ч). Вероятность закрытия падает на 45% | D10: =calc_engine!C5 | E10: =ROUND(D10 * 0.45, 0) | F10: 🔴 P0 (Критический) | G10: Авторадар зависания сделок + эскалация РОПу на 3-й день | H10: ="+45% к конверсии этапа КП в оплату"
A11: 3 | B11: РОП — «играющий тренер» и узкое горлышко | C11: РОП ведет 80% сделок и перегружен (нагрузка 80%), а КАМы простаивают с 4% загрузки. Сделки тухнут без внимания | D11: =SUMIFS(raw_deals!$C$2:$C50000, raw_deals!$H$2:$H50000, 101, raw_deals!$D$2:$D50000, "<=5") | E11: =ROUND(D11 * 0.3, 0) | F11: 🔴 P0 (Критический) | G11: Матрица емкости (Capacity Planning) + автоперелив сделок на КАМов | H11: Разгрузка РОПа на 60% для управления и коучинга
A12: 4 | B12: Менеджеры-автоответчики и слив звонков | C12: В 33% звонков не зафиксирован Next Step. Средний балл речи < 9/13. Лиды уходят в «подумаю» | D12: =calc_engine!B17 | E12: =ROUND(D12 * 0.25, 0) | F12: 🔴 P0 (Критический) | G12: 13-факторная речевая аналитика + чек-листы BANT + мотивация от речи | H12: ="+30% к конверсии из первого звонка во встречу"
A13: 5 | B13: «Кладбище отказников» без реактивации | C13: 1 млн ₽ списан в отказ (L1 «дорого», L2 «подумаю»). База брошена в архиве без повторного прогрева | D13: =SUM(calc_engine!D52:D55) | E13: =calc_engine!D56 | F13: 🟡 P1 (Высокий) | G13: Agentic AI Recovery Engine: сегментация отказников + офферы даунсейла | H13: Возврат до 20–30% списанной выручки из архива
A14: 6 | B14: Зависшая дебиторка и кассовые разрывы | C14: Счета выставлены, но не оплачены (DSO > 25 дней). 330к просрочки грозит кассовым разрывом | D14: =calc_engine!B146 | E14: =D14 | F14: 🟡 P1 (Высокий) | G14: Платежный календарь DSO + триггерные AI-уведомления бухгалтерии клиента | H14: Сокращение срока дебиторки DSO с 27 до 7 дней
A15: 7 | B15: Слив маркетинга и война с отделом продаж | C15: Google Ads слил 85 000 ₽ с ROMI -100% (0 оплат). Деньги сожжены без сквозного контроля окупаемости | D15: =SUMIF(raw_marketing!$B$2:$B50000, "Google Ads", raw_marketing!$E$2:$E50000) | E15: =D15 | F15: 🟡 P1 (Высокий) | G15: Сквозная RevOps-атрибуция W-Shaped: автоотключение убыточных связок | H15: Экономия рекламного бюджета + перелив в прибыльный Контур/Директ
B16: ИТОГО ВЫЯВЛЕННЫХ ПОТЕРЬ И РИСКОВ В МЕСЯЦ: | D16: =SUM(D9:D15) | E16: =SUM(E9:E15) | F16: ИТОГО ПОТЕРЬ | G16: Потенциал возврата в кассу | H16: Окупаемость за счет устранения узких мест
A18: 🚀 ЭКОНОМИКА ПРОЕКТА ОПТИМИЗАЦИИ И СРОК ОКУПАЕМОСТИ ДЛЯ КЛИЕНТА
A19: Параметр экономики проекта | B19: Значение | C19: Комментарий и логика расчета
A20: Стоимость проекта оптимизации ОП | B20: 450000 | C20: Фиксированная стоимость внедрения (4 недели спринтов)
A21: Ожидаемый возврат выручки (M1 факт) | B21: =ROUND(E16 * 0.3, 0) | C21: Консервативный ориентир: устранение всего 30% найденных узких мест
A22: Чистая прибыль собственника за вычетом услуг | B22: =B21 - B20 | C22: Чистый денежный плюс в кассе компании в первый же месяц
A23: Чистый ROI инвестиций в проект | B23: =ROUND((B21 - B20) / B20 * 100, 0) & "%" | C23: Процент отдачи на каждый вложенный рубль
A24: Срок полной окупаемости проекта | B24: =ROUND(B20 / (B21 / 30), 0) & " дн." | C24: Количество дней работы ОП до полной окупаемости чека внедрения
A26: 👉 УТВЕРДИТЬ ПРОЕКТ ОПТИМИЗАЦИИ И СФОРМИРОВАТЬ ИНВОЙС (450 000 ₽)
A27: =HYPERLINK("#'⚡ Экспресс_Калькулятор_3_Цифры'!A1", "Не готовы к спринту? 👉 Бесплатный тест-драйв на 3 звонках в Экспресс-Калькуляторе")
A28: 🔒 Безопасный B2B-расчет: безналичный платеж по счету (УПД / Диадок) • 152-ФЗ РФ • Старт спринта за 24 часа

Sheet 📄 Executive_OnePager
A1: 📄 REVOPS ENTERPRISE EXECUTIVE ONE-PAGER (УПРАВЛЕНЧЕСКИЙ ДАЙДЖЕСТ РУКОВОДСТВА)
A2: =HYPERLINK("#'📄 Executive_OnePager'!A1", "📄 1. One-Pager") | B2: =HYPERLINK("#'⚡ Пульс_Компании'!A1", "⚡ 2. Пульс компании") | C2: =HYPERLINK("#'📋 Пульт_РОПа_15_Минут'!A1", "📋 3. Пульт РОПа") | D2: =HYPERLINK("#'💸 Диагностика_Утечек_ОП'!A1", "💸 4. 7 Грехов ОП") | E2: =HYPERLINK("#'🎯 Action_Center'!A1", "🎯 5. Action Center") | F2: =HYPERLINK("#'🎙️ ИИ_Аудит'!A1", "🎙️ 6. ИИ-Аудит") | G2: =HYPERLINK("#'⚡ Экспресс_Калькулятор_3_Цифры'!A1", "⚡ 7. Экспресс 3 цифры") | H2: =HYPERLINK("#'🧪 QA_Suite'!A1", "🧪 8. QA Suite") | I2: =HYPERLINK("#'⚙️ Настройки'!A1", "⚙️ 9. Настройки")
A4: Выручка (Факт Closed-Won) | B4: % Выполнения плана | C4: Взвешенный прогноз (SSOT) | D4: Run-Rate касса (Прогноз) | E4: Активный пайплайн в работе | F4: Сделок под угрозой SLA | G4: Качество речи ОП (ИИ) | H4: Data Quality Index
A5: =calc_engine!B19 | B5: =calc_engine!B20 | C5: =calc_engine!B18 | D5: =calc_engine!B29 | E5: =calc_engine!B17 | F5: =COUNTIF('🎯 Action_Center'!$E$2:$E$50, "*P0*") | G5: =AVERAGE(raw_calls!$T$2:$T$50000)/13 | H5: ='📊 Data_Quality'!$C$8
A7: 📊 ВОРОНКА ПРОДАЖ & УЗКИЕ ГОРЛЫШКИ (AS-IS) | F7: 🚨 ТОП-5 КРИТИЧЕСКИХ РИСКОВ ВЫРУЧКИ (ACTION CENTER)
A8: Этап сделки | B8: Сделок | C8: Объем, ₽ | D8: SLA норматив (ч) | F8: Сделка / Клиент | G8: Проблема & Симптом | H8: Сумма в риске, ₽ | I8: Срочное действие РОПа
A9: 1. Новый лид | B9: ='⚡ Пульс_Компании'!B10 | C9: ='⚡ Пульс_Компании'!C10 | D9: 24 | F9: D-104 | G9: ='🎯 Action_Center'!B2 | H9: ='🎯 Action_Center'!D2 | I9: ='🎯 Action_Center'!F2
A10: 2. Квалификация / ЛПР | B10: ='⚡ Пульс_Компании'!B11 | C10: ='⚡ Пульс_Компании'!C11 | D10: 48 | F10: D-103 | G10: ='🎯 Action_Center'!B3 | H10: ='🎯 Action_Center'!D3 | I10: ='🎯 Action_Center'!F3
A11: 3. Встреча / Демо | B11: ='⚡ Пульс_Компании'!B12 | C11: ='⚡ Пульс_Компании'!C12 | D11: 120 | F11: D-109 | G11: ='🎯 Action_Center'!B4 | H11: ='🎯 Action_Center'!D4 | I11: ='🎯 Action_Center'!F4
A12: 4. КП и согласование | B12: ='⚡ Пульс_Компании'!B13 | C12: ='⚡ Пульс_Компании'!C13 | D12: 48 | F12: D-106 | G12: ='🎯 Action_Center'!B5 | H12: ='🎯 Action_Center'!D5 | I12: ='🎯 Action_Center'!F5
A13: 5. Счет выставлен | B13: ='⚡ Пульс_Компании'!B14 | C13: ='⚡ Пульс_Компании'!C14 | D13: 72 | F13: D-107 | G13: ='🎯 Action_Center'!B6 | H13: ='🎯 Action_Center'!D6 | I13: ='🎯 Action_Center'!F6
A14: 6. Успешно реализовано | B14: ='⚡ Пульс_Компании'!B15 | C14: ='⚡ Пульс_Компании'!C15 | D14: 0
A16: 🎯 ГЛАВНЫЙ ФОКУС РУКОВОДСТВА ДО КОНЦА МЕСЯЦА: Перехват сделки D-104 (850 000 ₽) и перераспределение 3 лидов с перегруженного РОПа на КАМов.

Sheet ⚙️ Настройки
A1: ⚙️ СИСТЕМНЫЕ КОНФИГУРАЦИИ И РЕЕСТР ДОПУЩЕНИЙ REVOPS OS PRO V17.6 (GOLDEN MASTER)
A2: =HYPERLINK("#'📄 Executive_OnePager'!A1", "📄 1. One-Pager") | B2: =HYPERLINK("#'⚡ Пульс_Компании'!A1", "⚡ 2. Пульс компании") | C2: =HYPERLINK("#'📋 Пульт_РОПа_15_Минут'!A1", "📋 3. Пульт РОПа") | D2: =HYPERLINK("#'💸 Диагностика_Утечек_ОП'!A1", "💸 4. 7 Грехов ОП") | E2: =HYPERLINK("#'🎯 Action_Center'!A1", "🎯 5. Action Center") | F2: =HYPERLINK("#'🎙️ ИИ_Аудит'!A1", "🎙️ 6. ИИ-Аудит") | G2: =HYPERLINK("#'⚡ Экспресс_Калькулятор_3_Цифры'!A1", "⚡ 7. Экспресс 3 цифры") | H2: =HYPERLINK("#'🧪 QA_Suite'!A1", "🧪 8. QA Suite") | I2: =HYPERLINK("#'⚙️ Настройки'!A1", "⚙️ 9. Настройки")
A3: Организация | B3: RevOps Enterprise | D3: 🔑 TENANT UUID: | E3: TENANT-MASTER-001 | F3: (Мастер-шаблон)
A4: Валюта системы | B4: RUB (₽) | D4: 🏢 ТЕНАНТ / КОМПАНИЯ: | E4: RevOps OS V18.0 Enterprise Release | F4: (Пространство вендора)
A5: Версия архитектуры | B5: RevOps Enterprise OS V17.6 Production Suite | C5: ⚡ БЫСТРЫЙ ВЫБОР ПЕРИОДА | D5: 🔒 СТАТУС RBAC: | E5: 🛡️ Hardware Enforcement (Protected Sheets) | F5: (Защищено через API)
A6: Период: начало | B6: 01.10.2026 | C6: Текущий месяц
A7: Период: конец | B7: 31.10.2026 | C7: (автозаполнение B6 и B7)
A8: Дата старта проекта | B8: 03.10.2026 | J8: 👥 ПЕРСОНАЛЬНЫЙ МАППИНГ РОЛЕЙ ПО EMAIL (MULTI-USER RBAC)
A9: План выручки на месяц | B9: 5000000 | C9: Enterprise Multi-Tenant V17.6 | D9: 🏢 Холдинг (Все филиалы) | E9: Статус контура: | F9: 🟢 152-ФЗ РФ Compliant (Аттестован) | G9: СЕССИЯ ПЛАНИРОВАНИЯ: | H9: 🟢 Готова к работе (Свободна) | J9: Корпоративный Email | K9: Назначенная роль | L9: Целевой Landing-дашборд
A10: 👤 РОЛЬ В СИСТЕМЕ: | B10: 👑 CEO | C10: 🎯 ВЫБОР ФОКУСА ДАННЫХ: | D10: Авто (По умолчанию роли) | E10: 👥 ФИЛЬТР СОТРУДНИКА: | F10: 👥 Весь отдел продаж (Сводно) | G10: РЕЖИМ ЭКСПЛУАТАЦИИ: | H10: 👥 Multi-User (Персональные фильтры) | J10: ceo@company.com | K10: 👑 CEO | L10: 📄 Executive_OnePager
A11: Stage ID | B11: Название этапа воронки | C11: SLA норматив (ч) | D11: Вероятность (Win %) | J11: rop@company.com | K11: 📋 РОП | L11: 📋 Пульт_РОПа_15_Минут
A12: 1 | B12: 1. Новый лид | C12: 24 | D12: 0.05 | J12: kam@company.com | K12: 💼 KAM | L12: ⚡ Пульс_Компании
A13: 2 | B13: 2. Квалификация / ЛПР | C13: 48 | D13: 0.15 | J13: sdr@company.com | K13: 📞 SDR | L13: ⚡ Пульс_Компании
A14: 3 | B14: 3. Встреча / Демо | C14: 120 | D14: 0.35 | J14: cmo@company.com | K14: 🌐 CMO | L14: 🌐 Маркетинг_и_Трафик
A15: 4 | B15: 4. КП и согласование | C15: 48 | D15: 0.6 | J15: cfo@company.com | K15: 💳 CFO | L15: 💳 Финансы_и_AI_Дожим
A16: 5 | B16: 5. Счет выставлен | C16: 72 | D16: 0.85 | J16: admin@company.com | K16: 🔧 Admin | L16: ⚙️ Настройки
A17: 6 | B17: 6. Успешно реализовано | C17: 0 | D17: 1
A18: 7 | B18: 7. Закрыто и не реализовано | C18: 0 | D18: 0
A20: ID | B20: Сотрудник | C20: Роль | D20: Лимит открытых сделок | E20: Статус емкости
A21: 101 | B21: Иванов Дмитрий (РОП) | C21: ROP | D21: 5 | E21: Жесткий лимит
A22: 102 | B22: Петров Александр (КАМ) | C22: KAM | D22: 25 | E22: Норма
A23: 103 | B23: Сидоров Роман (SDR) | C23: SDR | D23: 40 | E23: Норма
A24: 104 | B24: Козлов Алексей (SDR-2) | C24: SDR | D24: 40 | E24: Норма
A25: Код срыва | B25: Причина отказа | C25: Вероятность реактивации
A26: L1 | B26: Дорого / нет бюджета | C26: 0.5
A27: L2 | B27: Выбрали конкурента | C27: 0.35
A28: L3 | B28: Не формат / нет потребности | C28: 0.1
A29: L4 | B29: Потеря контакта / недозвон | C29: 0.2
A31: 📦 МОДУЛЬНЫЙ КОНСТРУКТОР ТАРИФОВ И РАСШИРЕНИЙ (FEATURE FLAGS)
A32: Код модуля | B32: Название модуля платформы RevOps | C32: Статус модуля | D32: Уровень тарифа | E32: Плата, ₽/мес
A33: MOD-01 | B33: 🎙️ Речевой ИИ-Супервайзер 100% звонков (Whisper + DeepSeek) | C33: ВКЛЮЧЕН | D33: Light | E33: 29,000 ₽
A34: MOD-02 | B34: ⚡ Мгновенные алерты в Telegram (30с со сценарием спасения) | C34: ВКЛЮЧЕН | D34: Pro | E34: 15,000 ₽
A35: MOD-03 | B35: 🤖 Автозаполнение CRM (Executive Summary + договоренности) | C35: ВКЛЮЧЕН | D35: Pro | E35: 19,000 ₽
A36: MOD-04 | B36: 🛡️ Пакет «Антисаботаж» и Режим «Адвокат менеджера» | C36: ВКЛЮЧЕН | D36: Pro | E36: 15,000 ₽
A37: MOD-05 | B37: 🎯 Контроль 13 B2B-стандартов речи и жесткого Next Step | C37: ВКЛЮЧЕН | D37: Pro | E37: 25,000 ₽
A38: MOD-06 | B38: 📊 Пульт РОПа 15 минут: утренний радар сливов и лидерборд | C38: ВКЛЮЧЕН | D38: Pro | E38: 35,000 ₽
A39: MOD-07 | B39: 🔐 Контур безопасности 152-ФЗ и токенизация биометрии | C39: ВКЛЮЧЕН | D39: Enterprise | E39: 25,000 ₽
A40: MOD-08 | B40: 📄 Executive OnePager генератор для Собственника и CFO | C40: ВКЛЮЧЕН | D40: Enterprise | E40: 20,000 ₽
A41: ⚡ БЕНЧМАРКИ И НОРМАТИВЫ ПОТЕРЬ (ФИНАНСОВЫЙ КАЛЬКУЛЯТОР) | D41: СУММАРНЫЙ MRR: | E41: 183,000 ₽
A42: Параметр бенчмарка | B42: Значение | C42: Комментарий
...

Sheet raw_touchpoints
A1: touch_id | B1: deal_id | C1: client_id | D1: touch_date | E1: channel | F1: campaign_id | G1: touch_stage | H1: weight_pct | I1: deal_amount | J1: is_won | K1: attributed_won_rev | L1: pipeline_attr_val | M1: synced_at | Z1: data_snapshot_date | AA1: data_version | AB1: uploaded_by | AC1: upload_hash
A2: TP-101 | B2: D-101 | C2: ga_11 | D2: 46259 | E2: Органика SEO | F2: cmp_seo | G2: 1. First Touch | H2: 0.3 | I2: =IFERROR(VLOOKUP(B2, raw_deals!$A$2:$C50000, 3, FALSE), 0) | J2: =IFERROR(VLOOKUP(B2, raw_deals!$A$2:$O50000, 15, FALSE), FALSE) | K2: =IF(J2=TRUE, I2*H2, 0) | L2: =IF(J2=FALSE, I2*H2*IFERROR(VLOOKUP(VLOOKUP(B2, raw_deals!$A$2:$D50000, 4, FALSE), '⚙️ Настройки'!$A$12:$D$18, 4, FALSE), 0), 0) | M2: 46294
A3: TP-102 | B3: D-101 | C3: ga_11 | D3: 46267 | E3: Яндекс Директ | F3: cmp_yd | G3: 2. Lead Creation | H3: 0.3 | I3: =IFERROR(VLOOKUP(B3, raw_deals!$A$2:$C50000, 3, FALSE), 0) | J3: =IFERROR(VLOOKUP(B3, raw_deals!$A$2:$O50000, 15, FALSE), FALSE) | K3: =IF(J3=TRUE, I3*H3, 0) | L3: =IF(J3=FALSE, I3*H3*IFERROR(VLOOKUP(VLOOKUP(B3, raw_deals!$A$2:$D50000, 4, FALSE), '⚙️ Настройки'!$A$12:$D$18, 4, FALSE), 0), 0) | M3: 46294
A4: TP-103 | B4: D-101 | C4: ga_11 | D4: 46272 | E4: Партнеры | F4: cmp_ref | G4: 3. Middle Nurture | H4: 0.1 | I4: =IFERROR(VLOOKUP(B4, raw_deals!$A$2:$C50000, 3, FALSE), 0) | J4: =IFERROR(VLOOKUP(B4, raw_deals!$A$2:$O50000, 15, FALSE), FALSE) | K4: =IF(J4=TRUE, I4*H4, 0) | L4: =IF(J4=FALSE, I4*H4*IFERROR(VLOOKUP(VLOOKUP(B4, raw_deals!$A$2:$D50000, 4, FALSE), '⚙️ Настройки'!$A$12:$D$18, 4, FALSE), 0), 0) | M4: 46294
A5: TP-104 | B5: D-101 | C5: ga_11 | D5: 46277 | E5: Google Ads | F5: cmp_ga | G5: 4. Deal Close | H5: 0.3 | I5: =IFERROR(VLOOKUP(B5, raw_deals!$A$2:$C50000, 3, FALSE), 0) | J5: =IFERROR(VLOOKUP(B5, raw_deals!$A$2:$O50000, 15, FALSE), FALSE) | K5: =IF(J5=TRUE, I5*H5, 0) | L5: =IF(J5=FALSE, I5*H5*IFERROR(VLOOKUP(VLOOKUP(B5, raw_deals!$A$2:$D50000, 4, FALSE), '⚙️ Настройки'!$A$12:$D$18, 4, FALSE), 0), 0) | M5: 46294
A6: TP-105 | B6: D-102 | C6: ga_12 | D6: 46262 | E6: Контур.Фокус | F6: cmp_kf | G6: 1. First Touch | H6: 0.3 | I6: =IFERROR(VLOOKUP(B6, raw_deals!$A$2:$C50000, 3, FALSE), 0) | J6: =IFERROR(VLOOKUP(B6, raw_deals!$A$2:$O50000, 15, FALSE), FALSE) | K6: =IF(J6=TRUE, I6*H6, 0) | L6: =IF(J6=FALSE, I6*H6*IFERROR(VLOOKUP(VLOOKUP(B6, raw_deals!$A$2:$D50000, 4, FALSE), '⚙️ Настройки'!$A$12:$D$18, 4, FALSE), 0), 0) | M6: 46294
A7: TP-106 | B7: D-102 | C7: ga_12 | D7: 46269 | E7: Яндекс Директ | F7: cmp_yd | G7: 2. Lead Creation | H7: 0.3 | I7: =IFERROR(VLOOKUP(B7, raw_deals!$A$2:$C50000, 3, FALSE), 0) | J7: =IFERROR(VLOOKUP(B7, raw_deals!$A$2:$O50000, 15, FALSE), FALSE) | K7: =IF(J7=TRUE, I7*H7, 0) | L7: =IF(J7=FALSE, I7*H7*IFERROR(VLOOKUP(VLOOKUP(B7, raw_deals!$A$2:$D50000, 4, FALSE), '⚙️ Настройки'!$A$12:$D$18, 4, FALSE), 0), 0) | M7: 46294
A8: TP-107 | B8: D-102 | C8: ga_12 | D8: 46275 | E8: Контур.Фокус | F8: cmp_kf | G8: 3. Middle Nurture | H8: 0.1 | I8: =IFERROR(VLOOKUP(B8, raw_deals!$A$2:$C50000, 3, FALSE), 0) | J8: =IFERROR(VLOOKUP(B8, raw_deals!$A$2:$O50000, 15, FALSE), FALSE) | K8: =IF(J8=TRUE, I8*H8, 0) | L8: =IF(J8=FALSE, I8*H8*IFERROR(VLOOKUP(VLOOKUP(B8, raw_deals!$A$2:$D50000, 4, FALSE), '⚙️ Настройки'!$A$12:$D$18, 4, FALSE), 0), 0) | M8: 46294
A9: TP-108 | B9: D-102 | C9: ga_12 | D9: 46281 | E9: Контур.Фокус | F9: cmp_kf | G9: 4. Deal Close | H9: 0.3 | I9: =IFERROR(VLOOKUP(B9, raw_deals!$A$2:$C50000, 3, FALSE), 0) | J9: =IFERROR(VLOOKUP(B9, raw_deals!$A$2:$O50000, 15, FALSE), FALSE) | K9: =IF(J9=TRUE, I9*H9, 0) | L9: =IF(J9=FALSE, I9*H9*IFERROR(VLOOKUP(VLOOKUP(B9, raw_deals!$A$2:$D50000, 4, FALSE), '⚙️ Настройки'!$A$12:$D$18, 4, FALSE), 0), 0) | M9: 46294
A10: TP-109 | B10: D-104 | C10: ga_14 | D10: 46277 | E10: Контур.Фокус | F10: cmp_kf | G10: 1. First Touch | H10: 0.3 | I10: =IFERROR(VLOOKUP(B10, raw_deals!$A$2:$C50000, 3, FALSE), 0) | J10: =IFERROR(VLOOKUP(B10, raw_deals!$A$2:$O50000, 15, FALSE), FALSE) | K10: =IF(J10=TRUE, I10*H10, 0) | L10: =IF(J10=FALSE, I10*H10*IFERROR(VLOOKUP(VLOOKUP(B10, raw_deals!$A$2:$D50000, 4, FALSE), '⚙️ Настройки'!$A$12:$D$18, 4, FALSE), 0), 0) | M10: 46294
A11: TP-110 | B11: D-104 | C11: ga_14 | D11: 46279 | E11: Яндекс Директ | F11: cmp_yd | G11: 2. Lead Creation | H11: 0.3 | I11: =IFERROR(VLOOKUP(B11, raw_deals!$A$2:$C50000, 3, FALSE), 0) | J11: =IFERROR(VLOOKUP(B11, raw_deals!$A$2:$O50000, 15, FALSE), FALSE) | K11: =IF(J11=TRUE, I11*H11, 0) | L11: =IF(J11=FALSE, I11*H11*IFERROR(VLOOKUP(VLOOKUP(B11, raw_deals!$A$2:$D50000, 4, FALSE), '⚙️ Настройки'!$A$12:$D$18, 4, FALSE), 0), 0) | M11: 46294
A12: TP-111 | B12: D-104 | C12: ga_14 | D12: 46283 | E12: Контур.Фокус | F12: cmp_kf | G12: 3. Middle Nurture | H12: 0.1 | I12: =IFERROR(VLOOKUP(B12, raw_deals!$A$2:$C50000, 3, FALSE), 0) | J12: =IFERROR(VLOOKUP(B12, raw_deals!$A$2:$O50000, 15, FALSE), FALSE) | K12: =IF(J12=TRUE, I12*H12, 0) | L12: =IF(J12=FALSE, I12*H12*IFERROR(VLOOKUP(VLOOKUP(B12, raw_deals!$A$2:$D50000, 4, FALSE), '⚙️ Настройки'!$A$12:$D$18, 4, FALSE), 0), 0) | M12: 46294
A13: TP-112 | B13: D-105 | C13: ga_15 | D13: 46266 | E13: Партнеры | F13: cmp_ref | G13: 1. First Touch | H13: 0.5 | I13: =IFERROR(VLOOKUP(B13, raw_deals!$A$2:$C50000, 3, FALSE), 0) | J13: =IFERROR(VLOOKUP(B13, raw_deals!$A$2:$O50000, 15, FALSE), FALSE) | K13: =IF(J13=TRUE, I13*H13, 0) | L13: =IF(J13=FALSE, I13*H13*IFERROR(VLOOKUP(VLOOKUP(B13, raw_deals!$A$2:$D50000, 4, FALSE), '⚙️ Настройки'!$A$12:$D$18, 4, FALSE), 0), 0) | M13: 46294
A14: TP-113 | B14: D-105 | C14: ga_15 | D14: 46280 | E14: Яндекс Директ | F14: cmp_yd | G14: 2. Lead Creation | H14: 0.5 | I14: =IFERROR(VLOOKUP(B14, raw_deals!$A$2:$C50000, 3, FALSE), 0) | J14: =IFERROR(VLOOKUP(B14, raw_deals!$A$2:$O50000, 15, FALSE), FALSE) | K14: =IF(J14=TRUE, I14*H14, 0) | L14: =IF(J14=FALSE, I14*H14*IFERROR(VLOOKUP(VLOOKUP(B14, raw_deals!$A$2:$D50000, 4, FALSE), '⚙️ Настройки'!$A$12:$D$18, 4, FALSE), 0), 0) | M14: 46294
A15: TP-111B | B15: D-104 | C15: ga_14 | D15: 46287 | E15: Яндекс Директ | F15: cmp_yd | G15: 4. Deal Close | H15: 0.3 | I15: =IFERROR(VLOOKUP(B15, raw_deals!$A$2:$C50000, 3, FALSE), 0) | J15: =IFERROR(VLOOKUP(B15, raw_deals!$A$2:$O50000, 15, FALSE), FALSE) | K15: =IF(J15=TRUE, I15*H15, 0) | L15: =IF(J15=FALSE, I15*H15*IFERROR(VLOOKUP(VLOOKUP(B15, raw_deals!$A$2:$D50000, 4, FALSE), '⚙️ Настройки'!$A$12:$D$18, 4, FALSE), 0), 0) | M15: 46294

Sheet raw_deals
A1: deal_id | B1: client_name | C1: amount | D1: stage_id | E1: stage_name | F1: created_date | G1: stage_changed_date | H1: manager_id | I1: segment_code | J1: lead_source | K1: client_id | L1: scoring_tier | M1: loss_code | N1: synced_at | O1: is_won | P1: is_lost | Q1: days_in_stage | R1: aging_cohort | S1: weighted_val | T1: cycle_days | U1: utm_source | V1: utm_medium | W1: utm_campaign | X1: yclid | Y1: gclid | Z1: data_snapshot_date | AA1: data_version | AB1: uploaded_by | AC1: upload_hash | AD1: next_action_type | AE1: next_action_date | AF1: next_action_owner | AG1: next_action_channel | AH1: next_action_health | AI1: deal_health_score
A2: D-101 | B2: ООО "Альфа Трейд" | C2: 450000 | D2: 6 | E2: 6. Успешно реализовано | F2: 46267 | G2: 46277 | H2: 102 | I2: SEG1 | J2: Яндекс Директ | K2: ga_11 | L2: A | N2: 46285.472 | O2: =IF(A2="","",D2=6) | P2: =IF(A2="","",D2=7) | Q2: =IF(A2="","",IF(D2>=6,0,IF(ISBLANK(G2),0,IF(calc_engine!$B$1>INT(G2),INT(calc_engine!$B$1-G2),0)))) | R2: =IF(A2="","",IF(D2>=6,"closed",IF(Q2<=3,"0-3",IF(Q2<=7,"4-7",IF(Q2<=14,"8-14",IF(Q2<=30,"15-30","zombie")))))) | S2: =IF(A2="","",C2*IFERROR(VLOOKUP(D2,'⚙️ Настройки'!$A$12:$D$18,4,FALSE),0)) | T2: =IF(A2="","",IF(D2>=6,IF(G2>F2,INT(G2-F2),1),IF(calc_engine!$B$1>INT(F2),INT(calc_engine!$B$1-F2),1))) | U2: yandex | V2: cpc | W2: retarget_b2b | X2: yclid_101 | Z2: =calc_engine!$B$1 | AH2: =IF(A2="","", IF(AD2="","🔴 NO NEXT ACTION", IF(AE2<calc_engine!$B$1,"🔴 OVERDUE", IF(AE2-calc_engine!$B$1<=1,"🟡 TODAY", IF(AE2-calc_engine!$B$1<=3,"🟢 SOON","🟢 PLANNED"))))) | AI2: =IF(A2="","", ROUND( IF(Q2<=1, 30, IF(Q2<=3, 20, IF(Q2<=7, 10, 0))) + IF(AD2<>"", 25, 0) + IF(T2<=14, 20, 10) + IF(I2="SEG1", 15, 10) + IF(C2>=500000, 10, 5), 0))
A3: D-102 | B3: АО "Северсталь Ресурс" | C3: 1200000 | D3: 6 | E3: 6. Успешно реализовано | F3: 46269 | G3: 46281 | H3: 101 | I3: SEG1 | J3: Контур.Фокус | K3: ga_12 | L3: A | N3: 46285.472 | O3: =IF(A3="","",D3=6) | P3: =IF(A3="","",D3=7) | Q3: =IF(A3="","",IF(D3>=6,0,IF(ISBLANK(G3),0,IF(calc_engine!$B$1>INT(G3),INT(calc_engine!$B$1-G3),0)))) | R3: =IF(A3="","",IF(D3>=6,"closed",IF(Q3<=3,"0-3",IF(Q3<=7,"4-7",IF(Q3<=14,"8-14",IF(Q3<=30,"15-30","zombie")))))) | S3: =IF(A3="","",C3*IFERROR(VLOOKUP(D3,'⚙️ Настройки'!$A$12:$D$18,4,FALSE),0)) | T3: =IF(A3="","",IF(D3>=6,IF(G3>F3,INT(G3-F3),1),IF(calc_engine!$B$1>INT(F3),INT(calc_engine!$B$1-F3),1))) | U3: kontur | V3: cold | W3: cold_parsing | Z3: =calc_engine!$B$1 | AH3: =IF(A3="","", IF(AD3="","🔴 NO NEXT ACTION", IF(AE3<calc_engine!$B$1,"🔴 OVERDUE", IF(AE3-calc_engine!$B$1<=1,"🟡 TODAY", IF(AE3-calc_engine!$B$1<=3,"🟢 SOON","🟢 PLANNED"))))) | AI3: =IF(A3="","", ROUND( IF(Q3<=1, 30, IF(Q3<=3, 20, IF(Q3<=7, 10, 0))) + IF(AD3<>"", 25, 0) + IF(T3<=14, 20, 10) + IF(I3="SEG1", 15, 10) + IF(C3>=500000, 10, 5), 0))
A4: D-103 | B4: ИП Смирнов О.В. | C4: 150000 | D4: 5 | E4: 5. Счет выставлен | F4: 46275 | G4: 46285 | H4: 103 | I4: SEG2 | J4: Google Ads | K4: ga_13 | L4: B | N4: 46285.472 | O4: =IF(A4="","",D4=6) | P4: =IF(A4="","",D4=7) | Q4: =IF(A4="","",IF(D4>=6,0,IF(ISBLANK(G4),0,IF(calc_engine!$B$1>INT(G4),INT(calc_engine!$B$1-G4),0)))) | R4: =IF(A4="","",IF(D4>=6,"closed",IF(Q4<=3,"0-3",IF(Q4<=7,"4-7",IF(Q4<=14,"8-14",IF(Q4<=30,"15-30","zombie")))))) | S4: =IF(A4="","",C4*IFERROR(VLOOKUP(D4,'⚙️ Настройки'!$A$12:$D$18,4,FALSE),0)) | T4: =IF(A4="","",IF(D4>=6,IF(G4>F4,INT(G4-F4),1),IF(calc_engine!$B$1>INT(F4),INT(calc_engine!$B$1-F4),1))) | U4: google | V4: cpc | W4: search_brand | Y4: gclid_103 | Z4: =calc_engine!$B$1 | AD4: счёт | AE4: 46293 | AF4: 102 | AG4: phone | AH4: =IF(A4="","", IF(AD4="","🔴 NO NEXT ACTION", IF(AE4<calc_engine!$B$1,"🔴 OVERDUE", IF(AE4-calc_engine!$B$1<=1,"🟡 TODAY", IF(AE4-calc_engine!$B$1<=3,"🟢 SOON","🟢 PLANNED"))))) | AI4: =IF(A4="","", ROUND( IF(Q4<=1, 30, IF(Q4<=3, 20, IF(Q4<=7, 10, 0))) + IF(AD4<>"", 25, 0) + IF(T4<=14, 20, 10) + IF(I4="SEG1", 15, 10) + IF(C4>=500000, 10, 5), 0))
A5: D-104 | B5: ООО "Вектор Плюс" | C5: 850000 | D5: 4 | E5: 4. КП и согласование | F5: 46277 | G5: 46282 | H5: 101 | I5: SEG1 | J5: Контур.Фокус | K5: ga_14 | L5: A | N5: 46285.472 | O5: =IF(A5="","",D5=6) | P5: =IF(A5="","",D5=7) | Q5: =IF(A5="","",IF(D5>=6,0,IF(ISBLANK(G5),0,IF(calc_engine!$B$1>INT(G5),INT(calc_engine!$B$1-G5),0)))) | R5: =IF(A5="","",IF(D5>=6,"closed",IF(Q5<=3,"0-3",IF(Q5<=7,"4-7",IF(Q5<=14,"8-14",IF(Q5<=30,"15-30","zombie")))))) | S5: =IF(A5="","",C5*IFERROR(VLOOKUP(D5,'⚙️ Настройки'!$A$12:$D$18,4,FALSE),0)) | T5: =IF(A5="","",IF(D5>=6,IF(G5>F5,INT(G5-F5),1),IF(calc_engine!$B$1>INT(F5),INT(calc_engine!$B$1-F5),1))) | U5: kontur | V5: cold | W5: cold_parsing | Z5: =calc_engine!$B$1 | AD5: КП | AE5: 46294 | AF5: 101 | AG5: email | AH5: =IF(A5="","", IF(AD5="","🔴 NO NEXT ACTION", IF(AE5<calc_engine!$B$1,"🔴 OVERDUE", IF(AE5-calc_engine!$B$1<=1,"🟡 TODAY", IF(AE5-calc_engine!$B$1<=3,"🟢 SOON","🟢 PLANNED"))))) | AI5: =IF(A5="","", ROUND( IF(Q5<=1, 30, IF(Q5<=3, 20, IF(Q5<=7, 10, 0))) + IF(AD5<>"", 25, 0) + IF(T5<=14, 20, 10) + IF(I5="SEG1", 15, 10) + IF(C5>=500000, 10, 5), 0))
A6: D-105 | B6: ООО "Глобал Инвест" | C6: 3000000 | D6: 4 | E6: 4. КП и согласование | F6: 46266 | G6: 46280 | H6: 102 | I6: Петров Александр (КАМ) | J6: Партнеры | K6: ga_15 | L6: A | N6: 46285.472 | O6: =IF(A6="","",D6=6) | P6: =IF(A6="","",D6=7) | Q6: =IF(A6="","",IF(D6>=6,0,IF(ISBLANK(G6),0,IF(calc_engine!$B$1>INT(G6),INT(calc_engine!$B$1-G6),0)))) | R6: =IF(A6="","",IF(D6>=6,"closed",IF(Q6<=3,"0-3",IF(Q6<=7,"4-7",IF(Q6<=14,"8-14",IF(Q6<=30,"15-30","zombie")))))) | S6: =IF(A6="","",C6*IFERROR(VLOOKUP(D6,'⚙️ Настройки'!$A$12:$D$18,4,FALSE),0)) | T6: =IF(A6="","",IF(D6>=6,IF(G6>F6,INT(G6-F6),1),IF(calc_engine!$B$1>INT(F6),INT(calc_engine!$B$1-F6),1))) | U6: partner | V6: referral | W6: ref_network | Z6: =calc_engine!$B$1 | AD6: КП | AE6: 46295 | AF6: 103 | AG6: meeting | AH6: =IF(A6="","", IF(AD6="","🔴 NO NEXT ACTION", IF(AE6<calc_engine!$B$1,"🔴 OVERDUE", IF(AE6-calc_engine!$B$1<=1,"🟡 TODAY", IF(AE6-calc_engine!$B$1<=3,"🟢 SOON","🟢 PLANNED"))))) | AI6: =IF(A6="","", ROUND( IF(Q6<=1, 30, IF(Q6<=3, 20, IF(Q6<=7, 10, 0))) + IF(AD6<>"", 25, 0) + IF(T6<=14, 20, 10) + IF(I6="SEG1", 15, 10) + IF(C6>=500000, 10, 5), 0))
A7: D-106 | B7: ООО "СнабСервис" | C7: 280000 | D7: 3 | E7: 3. Встреча / Демо | F7: 46279 | G7: 46291 | H7: 102 | I7: SEG2 | J7: Яндекс Директ | K7: ga_16 | L7: B | N7: 46285.472 | O7: =IF(A7="","",D7=6) | P7: =IF(A7="","",D7=7) | Q7: =IF(A7="","",IF(D7>=6,0,IF(ISBLANK(G7),0,IF(calc_engine!$B$1>INT(G7),INT(calc_engine!$B$1-G7),0)))) | R7: =IF(A7="","",IF(D7>=6,"closed",IF(Q7<=3,"0-3",IF(Q7<=7,"4-7",IF(Q7<=14,"8-14",IF(Q7<=30,"15-30","zombie")))))) | S7: =IF(A7="","",C7*IFERROR(VLOOKUP(D7,'⚙️ Настройки'!$A$12:$D$18,4,FALSE),0)) | T7: =IF(A7="","",IF(D7>=6,IF(G7>F7,INT(G7-F7),1),IF(calc_engine!$B$1>INT(F7),INT(calc_engine!$B$1-F7),1))) | U7: yandex | V7: cpc | W7: search_rf | X7: yclid_106 | Z7: =calc_engine!$B$1 | AD7: встреча | AE7: 46297 | AF7: 102 | AG7: meeting | AH7: =IF(A7="","", IF(AD7="","🔴 NO NEXT ACTION", IF(AE7<calc_engine!$B$1,"🔴 OVERDUE", IF(AE7-calc_engine!$B$1<=1,"🟡 TODAY", IF(AE7-calc_engine!$B$1<=3,"🟢 SOON","🟢 PLANNED"))))) | AI7: =IF(A7="","", ROUND( IF(Q7<=1, 30, IF(Q7<=3, 20, IF(Q7<=7, 10, 0))) + IF(AD7<>"", 25, 0) + IF(T7<=14, 20, 10) + IF(I7="SEG1", 15, 10) + IF(C7>=500000, 10, 5), 0))
A8: D-107 | B8: ИП Николаев А.С. | C8: 120000 | D8: 2 | E8: 2. Квалификация / ЛПР | F8: 46280 | G8: 46293 | H8: 103 | I8: SEG2 | J8: Органика SEO | K8: ga_17 | L8: C | N8: 46285.472 | O8: =IF(A8="","",D8=6) | P8: =IF(A8="","",D8=7) | Q8: =IF(A8="","",IF(D8>=6,0,IF(ISBLANK(G8),0,IF(calc_engine!$B$1>INT(G8),INT(calc_engine!$B$1-G8),0)))) | R8: =IF(A8="","",IF(D8>=6,"closed",IF(Q8<=3,"0-3",IF(Q8<=7,"4-7",IF(Q8<=14,"8-14",IF(Q8<=30,"15-30","zombie")))))) | S8: =IF(A8="","",C8*IFERROR(VLOOKUP(D8,'⚙️ Настройки'!$A$12:$D$18,4,FALSE),0)) | T8: =IF(A8="","",IF(D8>=6,IF(G8>F8,INT(G8-F8),1),IF(calc_engine!$B$1>INT(F8),INT(calc_engine!$B$1-F8),1))) | U8: organic | V8: search | W8: seo_blog | Z8: =calc_engine!$B$1 | AD8: звонок | AE8: 46300 | AF8: 103 | AG8: phone | AH8: =IF(A8="","", IF(AD8="","🔴 NO NEXT ACTION", IF(AE8<calc_engine!$B$1,"🔴 OVERDUE", IF(AE8-calc_engine!$B$1<=1,"🟡 TODAY", IF(AE8-calc_engine!$B$1<=3,"🟢 SOON","🟢 PLANNED"))))) | AI8: =IF(A8="","", ROUND( IF(Q8<=1, 30, IF(Q8<=3, 20, IF(Q8<=7, 10, 0))) + IF(AD8<>"", 25, 0) + IF(T8<=14, 20, 10) + IF(I8="SEG1", 15, 10) + IF(C8>=500000, 10, 5), 0))
A9: D-108 | B9: ООО "Ритейл Групп" | C9: 950000 | D9: 1 | E9: 1. Новый лид | F9: 46283 | G9: 46294 | H9: 103 | I9: SEG1 | J9: Контур.Фокус | K9: ga_18 | L9: A | N9: 46285.472 | O9: =IF(A9="","",D9=6) | P9: =IF(A9="","",D9=7) | Q9: =IF(A9="","",IF(D9>=6,0,IF(ISBLANK(G9),0,IF(calc_engine!$B$1>INT(G9),INT(calc_engine!$B$1-G9),0)))) | R9: =IF(A9="","",IF(D9>=6,"closed",IF(Q9<=3,"0-3",IF(Q9<=7,"4-7",IF(Q9<=14,"8-14",IF(Q9<=30,"15-30","zombie")))))) | S9: =IF(A9="","",C9*IFERROR(VLOOKUP(D9,'⚙️ Настройки'!$A$12:$D$18,4,FALSE),0)) | T9: =IF(A9="","",IF(D9>=6,IF(G9>F9,INT(G9-F9),1),IF(calc_engine!$B$1>INT(F9),INT(calc_engine!$B$1-F9),1))) | U9: kontur | V9: cold | W9: cold_parsing | Z9: =calc_engine!$B$1 | AD9: звонок | AE9: 46295 | AF9: 103 | AG9: phone | AH9: =IF(A9="","", IF(AD9="","🔴 NO NEXT ACTION", IF(AE9<calc_engine!$B$1,"🔴 OVERDUE", IF(AE9-calc_engine!$B$1<=1,"🟡 TODAY", IF(AE9-calc_engine!$B$1<=3,"🟢 SOON","🟢 PLANNED"))))) | AI9: =IF(A9="","", ROUND( IF(Q9<=1, 30, IF(Q9<=3, 20, IF(Q9<=7, 10, 0))) + IF(AD9<>"", 25, 0) + IF(T9<=14, 20, 10) + IF(I9="SEG1", 15, 10) + IF(C9>=500000, 10, 5), 0))
A10: D-109 | B10: ООО "ПромКомплект" | C10: 600000 | D10: 7 | E10: 7. Закрыто и не реализовано | F10: 46268 | G10: 46275 | H10: 102 | I10: SEG1 | J10: Яндекс Директ | K10: ga_19 | L10: A | M10: L1 | N10: 46285.472 | O10: =IF(A10="","",D10=6) | P10: =IF(A10="","",D10=7) | Q10: =IF(A10="","",IF(D10>=6,0,IF(ISBLANK(G10),0,IF(calc_engine!$B$1>INT(G10),INT(calc_engine!$B$1-G10),0)))) | R10: =IF(A10="","",IF(D10>=6,"closed",IF(Q10<=3,"0-3",IF(Q10<=7,"4-7",IF(Q10<=14,"8-14",IF(Q10<=30,"15-30","zombie")))))) | S10: =IF(A10="","",C10*IFERROR(VLOOKUP(D10,'⚙️ Настройки'!$A$12:$D$18,4,FALSE),0)) | T10: =IF(A10="","",IF(D10>=6,IF(G10>F10,INT(G10-F10),1),IF(calc_engine!$B$1>INT(F10),INT(calc_engine!$B$1-F10),1))) | U10: yandex | V10: cpc | W10: retarget_b2b | X10: yclid_109 | Z10: =calc_engine!$B$1 | AH10: =IF(A10="","", IF(AD10="","🔴 NO NEXT ACTION", IF(AE10<calc_engine!$B$1,"🔴 OVERDUE", IF(AE10-calc_engine!$B$1<=1,"🟡 TODAY", IF(AE10-calc_engine!$B$1<=3,"🟢 SOON","🟢 PLANNED"))))) | AI10: =IF(A10="","", ROUND( IF(Q10<=1, 30, IF(Q10<=3, 20, IF(Q10<=7, 10, 0))) + IF(AD10<>"", 25, 0) + IF(T10<=14, 20, 10) + IF(I10="SEG1", 15, 10) + IF(C10>=500000, 10, 5), 0))
A11: D-110 | B11: ЗАО "ТехноМаш" | C11: 400000 | D11: 7 | E11: 7. Закрыто и не реализовано | F11: 46270 | G11: 46279 | H11: 102 | I11: SEG2 | J11: Google Ads | K11: ga_20 | L11: B | M11: L2 | N11: 46285.472 | O11: =IF(A11="","",D11=6) | P11: =IF(A11="","",D11=7) | Q11: =IF(A11="","",IF(D11>=6,0,IF(ISBLANK(G11),0,IF(calc_engine!$B$1>INT(G11),INT(calc_engine!$B$1-G11),0)))) | R11: =IF(A11="","",IF(D11>=6,"closed",IF(Q11<=3,"0-3",IF(Q11<=7,"4-7",IF(Q11<=14,"8-14",IF(Q11<=30,"15-30","zombie")))))) | S11: =IF(A11="","",C11*IFERROR(VLOOKUP(D11,'⚙️ Настройки'!$A$12:$D$18,4,FALSE),0)) | T11: =IF(A11="","",IF(D11>=6,IF(G11>F11,INT(G11-F11),1),IF(calc_engine!$B$1>INT(F11),INT(calc_engine!$B$1-F11),1))) | U11: google | V11: cpc | W11: search_brand | Y11: gclid_110 | Z11: =calc_engine!$B$1 | AH11: =IF(A11="","", IF(AD11="","🔴 NO NEXT ACTION", IF(AE11<calc_engine!$B$1,"🔴 OVERDUE", IF(AE11-calc_engine!$B$1<=1,"🟡 TODAY", IF(AE11-calc_engine!$B$1<=3,"🟢 SOON","🟢 PLANNED"))))) | AI11: =IF(A11="","", ROUND( IF(Q11<=1, 30, IF(Q11<=3, 20, IF(Q11<=7, 10, 0))) + IF(AD11<>"", 25, 0) + IF(T11<=14, 20, 10) + IF(I11="SEG1", 15, 10) + IF(C11>=500000, 10, 5), 0))
A12: D-099 | B12: ООО "ПромСбыт" | C12: 180000 | D12: 5 | E12: 5. Счет выставлен | F12: 46235 | G12: 46244 | H12: 103 | I12: SEG2 | J12: Яндекс Директ | K12: ga_08 | L12: Tier B | N12: 46259 | O12: =IF(A12="","",D12=6) | P12: =IF(A12="","",D12=7) | Q12: =IF(A12="","",IF(D12>=6,0,IF(ISBLANK(G12),0,IF(calc_engine!$B$1>INT(G12),INT(calc_engine!$B$1-G12),0)))) | R12: =IF(A12="","",IF(D12>=6,"closed",IF(Q12<=3,"0-3",IF(Q12<=7,"4-7",IF(Q12<=14,"8-14",IF(Q12<=30,"15-30","zombie")))))) | S12: =IF(A12="","",C12*IFERROR(VLOOKUP(D12,'⚙️ Настройки'!$A$12:$D$18,4,FALSE),0)) | T12: =IF(A12="","",IF(D12>=6,IF(G12>F12,INT(G12-F12),1),IF(calc_engine!$B$1>INT(F12),INT(calc_engine!$B$1-F12),1))) | U12: yandex | V12: cpc | W12: b2b_context | Z12: =calc_engine!$B$1 | AD12: follow-up | AE12: 46292 | AF12: 101 | AG12: whatsapp | AH12: =IF(A12="","", IF(AD12="","🔴 NO NEXT ACTION", IF(AE12<calc_engine!$B$1,"🔴 OVERDUE", IF(AE12-calc_engine!$B$1<=1,"🟡 TODAY", IF(AE12-calc_engine!$B$1<=3,"🟢 SOON","🟢 PLANNED"))))) | AI12: =IF(A12="","", ROUND( IF(Q12<=1, 30, IF(Q12<=3, 20, IF(Q12<=7, 10, 0))) + IF(AD12<>"", 25, 0) + IF(T12<=14, 20, 10) + IF(I12="SEG1", 15, 10) + IF(C12>=500000, 10, 5), 0))
O13: =IF(A13="","",D13=6) | P13: =IF(A13="","",D13=7) | Q13: =IF(A13="","",IF(D13>=6,0,IF(ISBLANK(G13),0,IF(calc_engine!$B$1>INT(G13),INT(calc_engine!$B$1-G13),0)))) | R13: =IF(A13="","",IF(D13>=6,"closed",IF(Q13<=3,"0-3",IF(Q13<=7,"4-7",IF(Q13<=14,"8-14",IF(Q13<=30,"15-30","zombie")))))) | S13: =IF(A13="","",C13*IFERROR(VLOOKUP(D13,'⚙️ Настройки'!$A$12:$D$18,4,FALSE),0)) | T13: =IF(A13="","",IF(D13>=6,IF(G13>F13,INT(G13-F13),1),IF(calc_engine!$B$1>INT(F13),INT(calc_engine!$B$1-F13),1)))

Sheet raw_calls
A1: call_id | B1: deal_id | C1: manager_id | D1: call_date | E1: duration_sec | F1: call_type | G1: cr1 | H1: cr2 | I1: cr3 | J1: cr4 | K1: cr5 | L1: cr6 | M1: cr7 | N1: cr8 | O1: cr9 | P1: cr10 | Q1: cr11 | R1: cr12 | S1: cr13 | T1: total_score | U1: next_step_flag | V1: error_summary | W1: ai_recommendation | X1: synced_at | Z1: data_snapshot_date | AA1: data_version | AB1: uploaded_by | AC1: upload_hash
A2: C-501 | B2: D-101 | C2: 102 | D2: 46275 | E2: 420 | F2: qualification | G2: 1 | H2: 1 | I2: 1 | J2: 1 | K2: 1 | L2: 1 | M2: 1 | N2: 1 | O2: 1 | P2: 1 | Q2: 1 | R2: 1 | S2: 1 | T2: =SUM(G2:S2) | U2: =T2>=9 | V2: Без дефектов | W2: Эталонный скрипт | X2: 46285.472
A3: C-502 | B3: D-104 | C3: 101 | D3: 46279 | E3: 310 | F3: negotiation | G3: 1 | H3: 1 | I3: 1 | J3: 1 | K3: 1 | L3: 0 | M3: 1 | N3: 1 | O3: 1 | P3: 1 | Q3: 0 | R3: 1 | S3: 1 | T3: =SUM(G3:S3) | U3: =T3>=9 | V3: Слабая отработка цены | W3: Предложить рассрочку | X3: 46285.472
A4: C-503 | B4: D-106 | C4: 102 | D4: 46281 | E4: 180 | F4: meeting_confirm | G4: 1 | H4: 1 | I4: 0 | J4: 0 | K4: 1 | L4: 0 | M4: 1 | N4: 1 | O4: 0 | P4: 0 | Q4: 0 | R4: 1 | S4: 0 | T4: =SUM(G4:S4) | U4: =T4>=9 | V4: Нет фиксации даты | W4: Закрывать на конкретный слот | X4: 46285.472
A5: C-504 | B5: D-107 | C5: 103 | D5: 46281 | E5: 540 | F5: qualification | G5: 1 | H5: 1 | I5: 1 | J5: 1 | K5: 1 | L5: 1 | M5: 1 | N5: 0 | O5: 1 | P5: 1 | Q5: 1 | R5: 1 | S5: 1 | T5: =SUM(G5:S5) | U5: =T5>=9 | V5: Не выявлен бюджет | W5: Уточнить вилку затрат | X5: 46285.472
A6: C-505 | B6: D-109 | C6: 102 | D6: 46273 | E6: 210 | F6: lost | G6: 1 | H6: 0 | I6: 0 | J6: 0 | K6: 0 | L6: 0 | M6: 0 | N6: 1 | O6: 0 | P6: 0 | Q6: 0 | R6: 0 | S6: 0 | T6: =SUM(G6:S6) | U6: =T6>=9 | V6: Срыв контакта | W6: Передать в автодожим WhatsApp | X6: 46285.472
A7: C-506 | B7: D-108 | C7: 103 | D7: 46283 | E7: 290 | F7: cold_inbound | G7: 1 | H7: 1 | I7: 1 | J7: 1 | K7: 1 | L7: 1 | M7: 1 | N7: 1 | O7: 1 | P7: 1 | Q7: 1 | R7: 1 | S7: 1 | T7: =SUM(G7:S7) | U7: =T7>=9 | V7: Без дефектов | W7: Быстрый перевод на этап встречи | X7: 46285.472

Sheet 🌐 Мультиканальная_Атрибуция
A1: 🌐 МУЛЬТИКАНАЛЬНАЯ АТРИБУЦИЯ ВЫРУЧКИ: W-SHAPED REVENUE ENGINE (V17.6)
A2: =HYPERLINK("#'📄 Executive_OnePager'!A1", "📄 1. One-Pager") | B2: =HYPERLINK("#'⚡ Пульс_Компании'!A1", "⚡ 2. Пульс компании") | C2: =HYPERLINK("#'📋 Пульт_РОПа_15_Минут'!A1", "📋 3. Пульт РОПа") | D2: =HYPERLINK("#'💸 Диагностика_Утечек_ОП'!A1", "💸 4. 7 Грехов ОП") | E2: =HYPERLINK("#'🎯 Action_Center'!A1", "🎯 5. Action Center") | F2: =HYPERLINK("#'🎙️ ИИ_Аудит'!A1", "🎙️ 6. ИИ-Аудит") | G2: =HYPERLINK("#'⚡ Экспресс_Калькулятор_3_Цифры'!A1", "⚡ 7. Экспресс 3 цифры") | H2: =HYPERLINK("#'🧪 QA_Suite'!A1", "🧪 8. QA Suite") | I2: =HYPERLINK("#'⚙️ Настройки'!A1", "⚙️ 9. Настройки")
A3: Выручка Closed-Won | B3: Маркетинговый бюджет | C3: W-Shaped ROMI | D3: Первое касание (Opener) | E3: Закрывающее (Closer) | F3: Взвешенный пайплайн W
A4: =calc_engine!E137 | B4: =calc_engine!B137 | C4: =calc_engine!G137 | D4: Контур.Фокус / SEO | E4: Google Ads / Контур | F4: =SUM(raw_touchpoints!$L$2:$L50000)
A6: ⚖️ 1. КАЛИБРОВКА МОДЕЛЕЙ АТРИБУЦИИ: FIRST-TOUCH vs LAST-TOUCH vs W-SHAPED
A7: Канал привлечения | B7: Расход, ₽ | C7: Last-Touch (V10) | D7: W-Shaped (V11) | E7: LT ROMI | F7: W-Shaped ROMI | G7: Дельта выручки, ₽ | H7: Эффект перераспределения | I7: Решение RevOps
A8: =calc_engine!A132 | B8: =calc_engine!B132 | C8: =calc_engine!D132 | D8: =calc_engine!E132 | E8: =calc_engine!G132 | F8: =calc_engine!H132 | G8: =D8-C8 | H8: =IF(G8>0, "🟢 НЕДООЦЕНЕН (+ " & TEXT(G8, "#,##0 ₽") & ")", IF(G8<0, "🔴 ПЕРЕОЦЕНЕН В V10 (" & TEXT(G8, "#,##0 ₽") & ")", "⚪ БЕЗ ИЗМЕНЕНИЙ")) | I8: =calc_engine!I132
A9: =calc_engine!A133 | B9: =calc_engine!B133 | C9: =calc_engine!D133 | D9: =calc_engine!E133 | E9: =calc_engine!G133 | F9: =calc_engine!H133 | G9: =D9-C9 | H9: =IF(G9>0, "🟢 НЕДООЦЕНЕН (+ " & TEXT(G9, "#,##0 ₽") & ")", IF(G9<0, "🔴 ПЕРЕОЦЕНЕН В V10 (" & TEXT(G9, "#,##0 ₽") & ")", "⚪ БЕЗ ИЗМЕНЕНИЙ")) | I9: =calc_engine!I133
A10: =calc_engine!A134 | B10: =calc_engine!B134 | C10: =calc_engine!D134 | D10: =calc_engine!E134 | E10: =calc_engine!G134 | F10: =calc_engine!H134 | G10: =D10-C10 | H10: =IF(G10>0, "🟢 НЕДООЦЕНЕН (+ " & TEXT(G10, "#,##0 ₽") & ")", IF(G10<0, "🔴 ПЕРЕОЦЕНЕН В V10 (" & TEXT(G10, "#,##0 ₽") & ")", "⚪ БЕЗ ИЗМЕНЕНИЙ")) | I10: =calc_engine!I134
A11: =calc_engine!A135 | B11: =calc_engine!B135 | C11: =calc_engine!D135 | D11: =calc_engine!E135 | E11: =calc_engine!G135 | F11: =calc_engine!H135 | G11: =D11-C11 | H11: =IF(G11>0, "🟢 НЕДООЦЕНЕН (+ " & TEXT(G11, "#,##0 ₽") & ")", IF(G11<0, "🔴 ПЕРЕОЦЕНЕН В V10 (" & TEXT(G11, "#,##0 ₽") & ")", "⚪ БЕЗ ИЗМЕНЕНИЙ")) | I11: =calc_engine!I135
A12: =calc_engine!A136 | B12: =calc_engine!B136 | C12: =calc_engine!D136 | D12: =calc_engine!E136 | E12: =calc_engine!G136 | F12: =calc_engine!H136 | G12: =D12-C12 | H12: =IF(G12>0, "🟢 НЕДООЦЕНЕН (+ " & TEXT(G12, "#,##0 ₽") & ")", IF(G12<0, "🔴 ПЕРЕОЦЕНЕН В V10 (" & TEXT(G12, "#,##0 ₽") & ")", "⚪ БЕЗ ИЗМЕНЕНИЙ")) | I12: =calc_engine!I136
A13: ИТОГО / БАЛАНС: | B13: =SUM(B8:B12) | C13: =SUM(C8:C12) | D13: =SUM(D8:D12) | E13: =calc_engine!F137 | F13: =calc_engine!G137 | G13: =SUM(G8:G12) | H13: ✅ 100% Баланс SSOT | I13: Полное сохранение выручки
A15: 🔄 2. РЕЕСТР СКВОЗНЫХ КАСАНИЙ КЛИЕНТОВ (CUSTOMER JOURNEY MULTI-TOUCH FEED)
A16: ID касания | B16: ID сделки | C16: Client ID | D16: Дата касания | E16: Канал касания | F16: Этап в цепочке | G16: Вес W-Shaped | H16: Атрибутированная выручка
A17: =raw_touchpoints!A2 | B17: =raw_touchpoints!B2 | C17: =raw_touchpoints!C2 | D17: =raw_touchpoints!D2 | E17: =raw_touchpoints!E2 | F17: =raw_touchpoints!G2 | G17: =raw_touchpoints!H2 | H17: =raw_touchpoints!K2
A18: =raw_touchpoints!A3 | B18: =raw_touchpoints!B3 | C18: =raw_touchpoints!C3 | D18: =raw_touchpoints!D3 | E18: =raw_touchpoints!E3 | F18: =raw_touchpoints!G3 | G18: =raw_touchpoints!H3 | H18: =raw_touchpoints!K3
A19: =raw_touchpoints!A4 | B19: =raw_touchpoints!B4 | C19: =raw_touchpoints!C4 | D19: =raw_touchpoints!D4 | E19: =raw_touchpoints!E4 | F19: =raw_touchpoints!G4 | G19: =raw_touchpoints!H4 | H19: =raw_touchpoints!K4
A20: =raw_touchpoints!A5 | B20: =raw_touchpoints!B5 | C20: =raw_touchpoints!C5 | D20: =raw_touchpoints!D5 | E20: =raw_touchpoints!E5 | F20: =raw_touchpoints!G5 | G20: =raw_touchpoints!H5 | H20: =raw_touchpoints!K5
A21: =raw_touchpoints!A6 | B21: =raw_touchpoints!B6 | C21: =raw_touchpoints!C6 | D21: =raw_touchpoints!D6 | E21: =raw_touchpoints!E6 | F21: =raw_touchpoints!G6 | G21: =raw_touchpoints!H6 | H21: =raw_touchpoints!K6
A22: =raw_touchpoints!A7 | B22: =raw_touchpoints!B7 | C22: =raw_touchpoints!C7 | D22: =raw_touchpoints!D7 | E22: =raw_touchpoints!E7 | F22: =raw_touchpoints!G7 | G22: =raw_touchpoints!H7 | H22: =raw_touchpoints!K7
A23: =raw_touchpoints!A8 | B23: =raw_touchpoints!B8 | C23: =raw_touchpoints!C8 | D23: =raw_touchpoints!D8 | E23: =raw_touchpoints!E8 | F23: =raw_touchpoints!G8 | G23: =raw_touchpoints!H8 | H23: =raw_touchpoints!K8
A24: =raw_touchpoints!A9 | B24: =raw_touchpoints!B9 | C24: =raw_touchpoints!C9 | D24: =raw_touchpoints!D9 | E24: =raw_touchpoints!E9 | F24: =raw_touchpoints!G9 | G24: =raw_touchpoints!H9 | H24: =raw_touchpoints!K9

Sheet 🧪 QA_Suite
A1: 118 РЕГРЕССИОННЫХ ТЕСТОВ (REVOPS ENTERPRISE V17.6)
